2021-09-30 08:55:09,694 INFO: Запуск Posts.ru [in C:\Р\Задачи\flask\posts.ru\app\__init__.py:44]
2021-09-30 08:55:40,937 INFO: Запуск Posts.ru [in C:\Р\Задачи\flask\posts.ru\app\__init__.py:44]
2021-09-30 11:42:02,665 INFO: Запуск Posts.ru [in C:\Р\Задачи\flask\posts.ru\app\__init__.py:44]
2021-09-30 11:44:22,554 INFO: Запуск Posts.ru [in C:\Р\Задачи\flask\posts.ru\app\__init__.py:44]
2021-09-30 11:45:37,938 INFO: Запуск Posts.ru [in C:\Р\Задачи\flask\posts.ru\app\__init__.py:44]
2021-09-30 12:14:24,842 INFO: Запуск Posts.ru [in C:\Р\Задачи\flask\posts.ru\app\__init__.py:44]
2021-09-30 12:15:10,685 ERROR: Exception on /user/user2 [GET] [in c:\р\задачи\flask\posts.ru\venv\lib\site-packages\flask\app.py:1454]
Traceback (most recent call last):
  File "c:\р\задачи\flask\posts.ru\venv\lib\site-packages\flask\app.py", line 2070, in wsgi_app
    response = self.full_dispatch_request()
  File "c:\р\задачи\flask\posts.ru\venv\lib\site-packages\flask\app.py", line 1515, in full_dispatch_request
    rv = self.handle_user_exception(e)
  File "c:\р\задачи\flask\posts.ru\venv\lib\site-packages\flask\app.py", line 1513, in full_dispatch_request
    rv = self.dispatch_request()
  File "c:\р\задачи\flask\posts.ru\venv\lib\site-packages\flask\app.py", line 1499, in dispatch_request
    return self.ensure_sync(self.view_functions[rule.endpoint])(**req.view_args)
  File "c:\р\задачи\flask\posts.ru\venv\lib\site-packages\flask_login\utils.py", line 272, in decorated_view
    return func(*args, **kwargs)
  File "C:\Р\Задачи\flask\posts.ru\app\routes.py", line 83, in user
    return render_template('user.html', title='Профиль пользователя', user=user, posts=posts)
  File "c:\р\задачи\flask\posts.ru\venv\lib\site-packages\flask\templating.py", line 147, in render_template
    return _render(
  File "c:\р\задачи\flask\posts.ru\venv\lib\site-packages\flask\templating.py", line 128, in _render
    rv = template.render(context)
  File "c:\р\задачи\flask\posts.ru\venv\lib\site-packages\jinja2\environment.py", line 1304, in render
    self.environment.handle_exception()
  File "c:\р\задачи\flask\posts.ru\venv\lib\site-packages\jinja2\environment.py", line 925, in handle_exception
    raise rewrite_traceback_stack(source=source)
  File "C:\Р\Задачи\flask\posts.ru\app\templates\user.html", line 1, in top-level template code
    {% extends 'base.html' %}
  File "C:\Р\Задачи\flask\posts.ru\app\templates\base.html", line 34, in top-level template code
    {% block content %}{% endblock %}
  File "C:\Р\Задачи\flask\posts.ru\app\templates\user.html", line 14, in block 'content'
    {% elif not current_user.is_folllowing(user) %}
  File "c:\р\задачи\flask\posts.ru\venv\lib\site-packages\jinja2\utils.py", line 84, in from_obj
    if hasattr(obj, "jinja_pass_arg"):
jinja2.exceptions.UndefinedError: 'app.models.Users object' has no attribute 'is_folllowing'
2021-09-30 12:16:32,788 ERROR: Exception on /user/user2 [GET] [in c:\р\задачи\flask\posts.ru\venv\lib\site-packages\flask\app.py:1454]
Traceback (most recent call last):
  File "c:\р\задачи\flask\posts.ru\venv\lib\site-packages\flask\app.py", line 2070, in wsgi_app
    response = self.full_dispatch_request()
  File "c:\р\задачи\flask\posts.ru\venv\lib\site-packages\flask\app.py", line 1515, in full_dispatch_request
    rv = self.handle_user_exception(e)
  File "c:\р\задачи\flask\posts.ru\venv\lib\site-packages\flask\app.py", line 1513, in full_dispatch_request
    rv = self.dispatch_request()
  File "c:\р\задачи\flask\posts.ru\venv\lib\site-packages\flask\app.py", line 1499, in dispatch_request
    return self.ensure_sync(self.view_functions[rule.endpoint])(**req.view_args)
  File "c:\р\задачи\flask\posts.ru\venv\lib\site-packages\flask_login\utils.py", line 272, in decorated_view
    return func(*args, **kwargs)
  File "C:\Р\Задачи\flask\posts.ru\app\routes.py", line 83, in user
    return render_template('user.html', title='Профиль пользователя', user=user, posts=posts)
  File "c:\р\задачи\flask\posts.ru\venv\lib\site-packages\flask\templating.py", line 147, in render_template
    return _render(
  File "c:\р\задачи\flask\posts.ru\venv\lib\site-packages\flask\templating.py", line 128, in _render
    rv = template.render(context)
  File "c:\р\задачи\flask\posts.ru\venv\lib\site-packages\jinja2\environment.py", line 1304, in render
    self.environment.handle_exception()
  File "c:\р\задачи\flask\posts.ru\venv\lib\site-packages\jinja2\environment.py", line 925, in handle_exception
    raise rewrite_traceback_stack(source=source)
  File "C:\Р\Задачи\flask\posts.ru\app\templates\user.html", line 1, in top-level template code
    {% extends 'base.html' %}
  File "C:\Р\Задачи\flask\posts.ru\app\templates\base.html", line 34, in top-level template code
    {% block content %}{% endblock %}
  File "C:\Р\Задачи\flask\posts.ru\app\templates\user.html", line 14, in block 'content'
    {% elif not current_user.is_following(user) %}
  File "c:\р\задачи\flask\posts.ru\venv\lib\site-packages\jinja2\utils.py", line 84, in from_obj
    if hasattr(obj, "jinja_pass_arg"):
jinja2.exceptions.UndefinedError: 'app.models.Users object' has no attribute 'is_folllowing'
2021-09-30 12:16:41,738 INFO: Запуск Posts.ru [in C:\Р\Задачи\flask\posts.ru\app\__init__.py:44]
2021-09-30 12:16:53,454 ERROR: Exception on /follow/user2 [GET] [in c:\р\задачи\flask\posts.ru\venv\lib\site-packages\flask\app.py:1454]
Traceback (most recent call last):
  File "c:\р\задачи\flask\posts.ru\venv\lib\site-packages\flask\app.py", line 2070, in wsgi_app
    response = self.full_dispatch_request()
  File "c:\р\задачи\flask\posts.ru\venv\lib\site-packages\flask\app.py", line 1515, in full_dispatch_request
    rv = self.handle_user_exception(e)
  File "c:\р\задачи\flask\posts.ru\venv\lib\site-packages\flask\app.py", line 1513, in full_dispatch_request
    rv = self.dispatch_request()
  File "c:\р\задачи\flask\posts.ru\venv\lib\site-packages\flask\app.py", line 1499, in dispatch_request
    return self.ensure_sync(self.view_functions[rule.endpoint])(**req.view_args)
  File "c:\р\задачи\flask\posts.ru\venv\lib\site-packages\flask_login\utils.py", line 272, in decorated_view
    return func(*args, **kwargs)
  File "C:\Р\Задачи\flask\posts.ru\app\routes.py", line 118, in follow
    flash('Вы подписаны на {}!'.format(usernname))
NameError: name 'usernname' is not defined
2021-09-30 12:17:16,682 INFO: Запуск Posts.ru [in C:\Р\Задачи\flask\posts.ru\app\__init__.py:44]
2021-09-30 12:17:46,546 ERROR: Exception on /follow/user2 [GET] [in c:\р\задачи\flask\posts.ru\venv\lib\site-packages\flask\app.py:1454]
Traceback (most recent call last):
  File "c:\р\задачи\flask\posts.ru\venv\lib\site-packages\flask\app.py", line 2070, in wsgi_app
    response = self.full_dispatch_request()
  File "c:\р\задачи\flask\posts.ru\venv\lib\site-packages\flask\app.py", line 1515, in full_dispatch_request
    rv = self.handle_user_exception(e)
  File "c:\р\задачи\flask\posts.ru\venv\lib\site-packages\flask\app.py", line 1513, in full_dispatch_request
    rv = self.dispatch_request()
  File "c:\р\задачи\flask\posts.ru\venv\lib\site-packages\flask\app.py", line 1499, in dispatch_request
    return self.ensure_sync(self.view_functions[rule.endpoint])(**req.view_args)
  File "c:\р\задачи\flask\posts.ru\venv\lib\site-packages\flask_login\utils.py", line 272, in decorated_view
    return func(*args, **kwargs)
  File "C:\Р\Задачи\flask\posts.ru\app\routes.py", line 118, in follow
    flash('Вы подписаны на {}!'.format(usernname))
NameError: name 'usernname' is not defined
2021-09-30 12:18:05,009 INFO: Запуск Posts.ru [in C:\Р\Задачи\flask\posts.ru\app\__init__.py:44]
